Workbook

Sheet Cover
B2: MIMIR LABS
B3: Five-Year Financial Model & P&L Projections
B4: Norn - Ratatosk - Ragnarok - Bifrost - Yggdrasil ERP
B6: Prepared July 2026 - Confidential, for investor discussion
B8: Basis | C8: Current canonical Yggdrasil pricing ($100K + $17.5K x Footprint Score); $800K pre-seed
B9: Year 1 | C9: Total revenue $380K - Net income $265K - cash-flow positive
B10: Year 5 | C10: Total revenue $23.8M - Recurring ARR $20.0M - Net income $19.8M
B11: Model | C11: Fully formula-driven: edit any highlighted driver on the Assumptions tab and every statement recalculates
B12: Tabs | C12: Assumptions - Revenue - Expenses - P&L - Cash & Runway - Cap Table - Unit Economics
B15: Figures reconcile to the canonical source docs. Non-Yggdrasil lines tie to the published projections; Yggdrasil is on current canonical pricing. Sales/BD commission is funded from sales revenue, not from the raise.

Sheet Assumptions
A1: Mimir Labs - Financial Model
A2: All figures USD. Highlighted cells are the editable drivers; every other tab computes from these. Basis: current canonical Yggdrasil pricing; $800K pre-seed raise.
C4: Year 1 | D4: Year 2 | E4: Year 3 | F4: Year 4 | G4: Year 5
A5: Yggdrasil ERP - pricing constants (canonical)
A6: Base annual license ($) | C6: 100000
A7: Per Footprint-point rate ($) | C7: 17500
A8: Representative license - Compliance Core ($) | C8: 150000
A9: Representative license - Operational Core ($) | C9: 220000
A10: Representative license - Regulated Enterprise ($) | C10: 380000
A11: Representative license - Strategic ($) | C11: 650000
A12: Pilot Track price ($) | C12: 55000
A13: Average activation fee ($) | C13: 75000
A14: Pilot-to-paid conversion credit ($) | C14: 27500
A15: Audit Authority attach rate (Y3+) | C15: 0.3
A16: Audit Authority regimes per opted tenant | C16: 1.2
A17: Audit Authority price per regime ($) | C17: 35000
A18: Yggdrasil ERP - adoption drivers (EOY tenant counts)
A19: Compliance Core tenants (EOY) | C19: 1 | D19: 4 | E19: 9 | F19: 17 | G19: 29
A20: Operational Core tenants (EOY) | C20: 0 | D20: 1 | E20: 3 | F20: 8 | G20: 18
A21: Regulated Enterprise tenants (EOY) | C21: 0 | D21: 0 | E21: 1 | F21: 3 | G21: 5
A22: Strategic tenants (EOY) | C22: 0 | D22: 0 | E22: 0 | F22: 0 | G22: 1
A23: Pilots sold (in year) | C23: 3 | D23: 8 | E23: 14 | F23: 25 | G23: 40
A24: Pilot -> paid conversions (in year) | C24: 1 | D24: 4 | E24: 8 | F24: 15 | G24: 25
A25: Norn (self-serve SaaS wedge)
A26: Active paid accounts (EOY) | C26: 24 | D26: 109 | E26: 389 | F26: 979 | G26: 1999
A27: Blended ARPA ($/mo) | C27: 140 | D27: 170 | E27: 200 | F27: 220 | G27: 240
A28: Ratatosk (governance services)
A29: Workshops delivered | C29: 4 | D29: 12 | E29: 28 | F29: 50 | G29: 75
A30: Avg engagement value ($) | C30: 8000 | D30: 9500 | E30: 11000 | F30: 12000 | G30: 13000
A31: Ragnarok (migration services)
A32: Migrations delivered | C32: 1 | D32: 6 | E32: 16 | F32: 30 | G32: 48
A33: Avg engagement value ($) | C33: 20000 | D33: 28000 | E33: 35000 | F33: 40000 | G33: 45000
A34: Bifrost (integration SaaS)
A35: Active subscribers (EOY) | C35: 0 | D35: 3 | E35: 12 | F35: 31 | G35: 64
A36: Blended monthly ($) | C36: 0 | D36: 2500 | E36: 2800 | F36: 3200 | G36: 3500
A37: Operating expenses
A38: Team size (FTE) | C38: 1 | D38: 3 | E38: 7 | F38: 14 | G38: 22
A39: Payroll + benefits ($) | C39: 0 | D39: 280000 | E39: 680000 | F39: 1400000 | G39: 2300000
A40: Founder draw ($) | C40: 60000 | D40: 80000 | E40: 120000 | F40: 150000 | G40: 180000
A41: Infrastructure (hosting, tools) ($) | C41: 12000 | D41: 36000 | E41: 96000 | F41: 200000 | G41: 380000
...

Sheet Revenue
A1: Revenue Build
A2: Every line computes from the Assumptions drivers. Yggdrasil rebuilt on canonical pricing; other lines tie to the published projections.
C4: Year 1 | D4: Year 2 | E4: Year 3 | F4: Year 4 | G4: Year 5
A5: Yggdrasil ERP
A6: Subscription ARR run-rate (EOY) | C6: =Assumptions!C19*Assumptions!C8+Assumptions!C20*Assumptions!C9+Assumptions!C21*Assumptions!C10+Assumptions!C22*Assumptions!C11 | D6: =Assumptions!D19*Assumptions!C8+Assumptions!D20*Assumptions!C9+Assumptions!D21*Assumptions!C10+Assumptions!D22*Assumptions!C11 | E6: =Assumptions!E19*Assumptions!C8+Assumptions!E20*Assumptions!C9+Assumptions!E21*Assumptions!C10+Assumptions!E22*Assumptions!C11 | F6: =Assumptions!F19*Assumptions!C8+Assumptions!F20*Assumptions!C9+Assumptions!F21*Assumptions!C10+Assumptions!F22*Assumptions!C11 | G6: =Assumptions!G19*Assumptions!C8+Assumptions!G20*Assumptions!C9+Assumptions!G21*Assumptions!C10+Assumptions!G22*Assumptions!C11
A7: Subscription revenue (recognized, mid-year) | C7: =C6/2 | D7: =(C6+D6)/2 | E7: =(D6+E6)/2 | F7: =(E6+F6)/2 | G7: =(F6+G6)/2
A8: Pilot Track revenue | C8: =Assumptions!C23*Assumptions!C12 | D8: =Assumptions!D23*Assumptions!C12 | E8: =Assumptions!E23*Assumptions!C12 | F8: =Assumptions!F23*Assumptions!C12 | G8: =Assumptions!G23*Assumptions!C12
A9: Activation revenue (net of pilot credit) | C9: =Assumptions!C24*(Assumptions!C13-Assumptions!C14) | D9: =Assumptions!D24*(Assumptions!C13-Assumptions!C14) | E9: =Assumptions!E24*(Assumptions!C13-Assumptions!C14) | F9: =Assumptions!F24*(Assumptions!C13-Assumptions!C14) | G9: =Assumptions!G24*(Assumptions!C13-Assumptions!C14)
A10: Audit Authority revenue (30% attach, Y3+) | C10: 0 | D10: 0 | E10: =(Assumptions!E19+Assumptions!E20+Assumptions!E21+Assumptions!E22)*Assumptions!C15*Assumptions!C16*Assumptions!C17 | F10: =(Assumptions!F19+Assumptions!F20+Assumptions!F21+Assumptions!F22)*Assumptions!C15*Assumptions!C16*Assumptions!C17 | G10: =(Assumptions!G19+Assumptions!G20+Assumptions!G21+Assumptions!G22)*Assumptions!C15*Assumptions!C16*Assumptions!C17
A11: Total Yggdrasil revenue | C11: =C7+C8+C9+C10 | D11: =D7+D8+D9+D10 | E11: =E7+E8+E9+E10 | F11: =F7+F8+F9+F10 | G11: =G7+G8+G9+G10
A13: Norn (SaaS)
A14: Norn ARR | C14: =Assumptions!C26*Assumptions!C27*12 | D14: =Assumptions!D26*Assumptions!D27*12 | E14: =Assumptions!E26*Assumptions!E27*12 | F14: =Assumptions!F26*Assumptions!F27*12 | G14: =Assumptions!G26*Assumptions!G27*12
A16: Ratatosk (services)
A17: Ratatosk revenue | C17: =Assumptions!C29*Assumptions!C30 | D17: =Assumptions!D29*Assumptions!D30 | E17: =Assumptions!E29*Assumptions!E30 | F17: =Assumptions!F29*Assumptions!F30 | G17: =Assumptions!G29*Assumptions!G30
A19: Ragnarok (services)
A20: Ragnarok revenue | C20: =Assumptions!C32*Assumptions!C33 | D20: =Assumptions!D32*Assumptions!D33 | E20: =Assumptions!E32*Assumptions!E33 | F20: =Assumptions!F32*Assumptions!F33 | G20: =Assumptions!G32*Assumptions!G33
A22: Bifrost (SaaS)
A23: Bifrost ARR | C23: =Assumptions!C35*Assumptions!C36*12 | D23: =Assumptions!D35*Assumptions!D36*12 | E23: =Assumptions!E35*Assumptions!E36*12 | F23: =Assumptions!F35*Assumptions!F36*12 | G23: =Assumptions!G35*Assumptions!G36*12
A25: Consolidated
A26: Total revenue | C26: =C11+C14+C17+C20+C23 | D26: =D11+D14+D17+D20+D23 | E26: =E11+E14+E17+E20+E23 | F26: =F11+F14+F17+F20+F23 | G26: =G11+G14+G17+G20+G23
A27: Recurring ARR (EOY: Norn+Bifrost+Ygg sub+AA) | C27: =C14+C23+C6+C10 | D27: =D14+D23+D6+D10 | E27: =E14+E23+E6+E10 | F27: =F14+F23+F6+F10 | G27: =G14+G23+G6+G10
A28: Recurring % of revenue | C28: =(C14+C23+C7+C10)/C26 | D28: =(D14+D23+D7+D10)/D26 | E28: =(E14+E23+E7+E10)/E26 | F28: =(F14+F23+F7+F10)/F26 | G28: =(G14+G23+G7+G10)/G26

Sheet Expenses
A1: Operating Expenses
A2: Opex-based model: delivery labor sits in payroll (lean, AI-augmented team). Drivers on the Assumptions tab.
C4: Year 1 | D4: Year 2 | E4: Year 3 | F4: Year 4 | G4: Year 5
A5: Team size (FTE) | C5: =Assumptions!C38 | D5: =Assumptions!D38 | E5: =Assumptions!E38 | F5: =Assumptions!F38 | G5: =Assumptions!G38
A6: Payroll + benefits | C6: =Assumptions!C39 | D6: =Assumptions!D39 | E6: =Assumptions!E39 | F6: =Assumptions!F39 | G6: =Assumptions!G39
A7: Founder draw | C7: =Assumptions!C40 | D7: =Assumptions!D40 | E7: =Assumptions!E40 | F7: =Assumptions!F40 | G7: =Assumptions!G40
A8: Infrastructure | C8: =Assumptions!C41 | D8: =Assumptions!D41 | E8: =Assumptions!E41 | F8: =Assumptions!F41 | G8: =Assumptions!G41
A9: Sales & marketing | C9: =Assumptions!C42 | D9: =Assumptions!D42 | E9: =Assumptions!E42 | F9: =Assumptions!F42 | G9: =Assumptions!G42
A10: Legal & accounting | C10: =Assumptions!C43 | D10: =Assumptions!D43 | E10: =Assumptions!E43 | F10: =Assumptions!F43 | G10: =Assumptions!G43
A11: Insurance & compliance | C11: =Assumptions!C44 | D11: =Assumptions!D44 | E11: =Assumptions!E44 | F11: =Assumptions!F44 | G11: =Assumptions!G44
A12: Travel | C12: =Assumptions!C45 | D12: =Assumptions!D45 | E12: =Assumptions!E45 | F12: =Assumptions!F45 | G12: =Assumptions!G45
A13: G&A | C13: =Assumptions!C46 | D13: =Assumptions!D46 | E13: =Assumptions!E46 | F13: =Assumptions!F46 | G13: =Assumptions!G46
A14: Total operating expenses | C14: =SUM(C6:C13) | D14: =SUM(D6:D13) | E14: =SUM(E6:E13) | F14: =SUM(F6:F13) | G14: =SUM(G6:G13)

Sheet P&L
A1: Income Statement (P&L)
A2: Five-year projection. Opex model (delivery in payroll). Pre-tax net income.
C4: Year 1 | D4: Year 2 | E4: Year 3 | F4: Year 4 | G4: Year 5
A5: Total revenue | C5: =Revenue!C26 | D5: =Revenue!D26 | E5: =Revenue!E26 | F5: =Revenue!F26 | G5: =Revenue!G26
A6: Operating expenses | C6: =-Expenses!C14 | D6: =-Expenses!D14 | E6: =-Expenses!E14 | F6: =-Expenses!F14 | G6: =-Expenses!G14
A7: Net income (pre-tax) | C7: =C5+C6 | D7: =D5+D6 | E7: =E5+E6 | F7: =F5+F6 | G7: =G5+G6
A8: Net margin | C8: =C7/C5 | D8: =D7/D5 | E8: =E7/E5 | F8: =F7/F5 | G8: =G7/G5
A9: Cumulative net income | C9: =C7 | D9: =C9+D7 | E9: =D9+E7 | F9: =E9+F7 | G9: =F9+G7
A11: Model reconciles to the canonical source docs (PROJECTIONS.md, COSTS.md). Non-Yggdrasil lines tie to the published projections; Yggdrasil rebuilt on current pricing ($100K + $17.5K x Footprint Score).

Sheet Cash & Runway
A1: Cash Flow & Runway
A2: Simplified: net income proxies operating cash flow. $800K raise closes in Year 1.
C4: Year 1 | D4: Year 2 | E4: Year 3 | F4: Year 4 | G4: Year 5
A5: Beginning cash | C5: =Assumptions!C48 | D5: =C8 | E5: =D8 | F5: =E8 | G5: =F8
A6: Capital raised (pre-seed) | C6: =Assumptions!C49 | D6: 0 | E6: 0 | F6: 0 | G6: 0
A7: Net income (from P&L) | C7: ='P&L'!C7 | D7: ='P&L'!D7 | E7: ='P&L'!E7 | F7: ='P&L'!F7 | G7: ='P&L'!G7
A8: Ending cash | C8: =C5+C6+C7 | D8: =D5+D6+D7 | E8: =E5+E6+E7 | F8: =F5+F6+F7 | G8: =G5+G6+G7
A10: The plan is cash-flow positive in Year 1 under canonical pricing; the pre-seed round is acceleration capital, not survival capital.
A11: $850K is available at the start (cash + raise) against ~$1.3M Year-1 gross opex - the model funds hiring ahead of the revenue it assumes.

Sheet Cap Table
A1: Cap Table & Use of Funds
A2: Pre-seed round. Pre-money set to preserve ~10% base equity at the $800K raise (see note).
A4: Round terms
A5: Pre-seed raise | C5: =Assumptions!C49
A6: Pre-money valuation | C6: =Assumptions!C50
A7: Post-money valuation | C7: =Assumptions!C50+Assumptions!C49
A8: Base equity issued | C8: =Assumptions!C49/(Assumptions!C50+Assumptions!C49)
A9: Founder ownership (base) | C9: =1-Assumptions!C49/(Assumptions!C50+Assumptions!C49)
A10: Performance warrants (max, portco-driven) | C10: 0.05
A11: Max total dilution (base + warrants) | C11: =Assumptions!C49/(Assumptions!C50+Assumptions!C49)+0.05
A13: Use of funds ($800K / ~18-month runway)
A14: Founder compensation (18 mo) | C14: 165000
A15: Hire 1 - Sr. Backend Engineer (15 mo) | C15: 175000
A16: Hire 2 - Sr. Frontend Engineer (12 mo) | C16: 145000
A17: Hire 3 - Sales / BD Lead (base; commission from sales) | C17: 65000
A18: Infrastructure & tooling | C18: 35000
A19: Legal, IP & SOC 2 prep | C19: 30000
A20: SOC 2 Type I audit | C20: 25000
A21: Sales & marketing (trade shows, content, travel) | C21: 70000
A22: Service delivery (Ratatosk/Ragnarok) | C22: 30000
A23: Operating reserve | C23: 60000
A24: Total | C24: =SUM(C14:C23)

Sheet Unit Economics
A1: Unit Economics & Valuation
A2: Reference metrics and Year-5 implied valuation range.
C4: Year 1 | D4: Year 2 | E4: Year 3 | F4: Year 4 | G4: Year 5
A5: Total revenue | C5: =Revenue!C26 | D5: =Revenue!D26 | E5: =Revenue!E26 | F5: =Revenue!F26 | G5: =Revenue!G26
A6: Recurring ARR (EOY) | C6: =Revenue!C27 | D6: =Revenue!D27 | E6: =Revenue!E27 | F6: =Revenue!F27 | G6: =Revenue!G27
A7: Recurring % of revenue | C7: =Revenue!C28 | D7: =Revenue!D28 | E7: =Revenue!E28 | F7: =Revenue!F28 | G7: =Revenue!G28
A8: Team size (FTE) | C8: =Expenses!C5 | D8: =Expenses!D5 | E8: =Expenses!E5 | F8: =Expenses!F5 | G8: =Expenses!G5
A9: Revenue per employee | C9: =Revenue!C26/Expenses!C5 | D9: =Revenue!D26/Expenses!D5 | E9: =Revenue!E26/Expenses!E5 | F9: =Revenue!F26/Expenses!F5 | G9: =Revenue!G26/Expenses!G5
A11: Year-5 implied valuation
A12: Year-5 recurring ARR | C12: =Revenue!G27
A13: ARR multiple - low (5x) | C13: =Revenue!G27*5
A14: ARR multiple - high (8x) | C14: =Revenue!G27*8
A15: Year-5 revenue | C15: =Revenue!G26
A16: Revenue multiple - low (3x) | C16: =Revenue!G26*3
A17: Revenue multiple - high (5x) | C17: =Revenue!G26*5
A19: Conservative Year-5 valuation range (mid-market vertical SaaS ARR multiples): ~$100M - $160M.
